Workbook

Sheet Sheet1
I1: No of installments Due | L1: 1
A3: SL NO | B3: Admsn No | C3: Name | D3: Name of Father | E3: ADDRESS | F3: DISTRICT | G3: PHONE | H3: Class | I3: Phone No | J3: Current Due | K3: Prev Balance | L3: Sem Fee (odd) | M3: Monthly Installment | N3: JUNE | O3: JuneReciept | P3: JULY | Q3: AUG | R3: SEP | S3: OCT | T3: NOV | U3: Paid | V3: Prev Balance 2 | W3: Sem Fee (Even) | X3: DEC | Y3: Jan | Z3: FEB | AA3: Bank / Cash | AB3: MAR | AC3: Bank / Cash 2 | AD3: APR | AE3: Bank / Cash 3 | AF3: May | AG3: Recieved | AH3: Balance2
A4: =ROW()-3 -> 1 | B4: 1 | C4: ABID ISMAIL | D4: =VLOOKUP(C4,Data!$B$2:$G$176,3,FALSE) -> V.U ISMAYEL | E4: =VLOOKUP(C4,Data!$B$2:$G$176,4,FALSE) -> Darul Aman (H), Vanchimala PO, Vanchimala (686508) , Elikkulam Panchayath | F4: =VLOOKUP(C4,Data!$B$2:$G$176,5,FALSE) -> Kottayam | G4: =VLOOKUP(C4,Data!$B$2:$G$176,6,FALSE) -> 9496432300 | H4: ILP 2 Commerce | J4: =K4+M4*$L$1-U4 -> 10000 | K4: 5000 | L4: 30000 | M4: =L4/6 -> 5000 | U4: =SUM(N4+P4+Q4+R4+S4+T4) -> 0
A5: =ROW()-3 -> 2 | B5: 2 | C5: AFSAL AMEEN PV | D5: =VLOOKUP(C5,Data!$B$2:$G$176,3,FALSE) -> ALI AKBAR P.V | E5: =VLOOKUP(C5,Data!$B$2:$G$176,4,FALSE) -> Pallikaravalappil, Wandoor, 8547225367 , | F5: =VLOOKUP(C5,Data!$B$2:$G$176,5,FALSE) -> Malappuram | G5: =VLOOKUP(C5,Data!$B$2:$G$176,6,FALSE) -> 0 | H5: ILP 2 Commerce | J5: =K5+M5*$L$1-U5 -> 15000 | K5: 10000 | L5: 30000 | M5: =L5/6 -> 5000 | U5: =SUM(N5+P5+Q5+R5+S5+T5) -> 0
A6: =ROW()-3 -> 3 | B6: 3 | C6: FIRDOUS MA | D6: =VLOOKUP(C6,Data!$B$2:$G$176,3,FALSE) -> ANSARI MI | E6: =VLOOKUP(C6,Data!$B$2:$G$176,4,FALSE) -> Murickolil H.Nadackal po Erattopetta kottayam, Erattupetta, 9961671818 , | F6: =VLOOKUP(C6,Data!$B$2:$G$176,5,FALSE) -> Kottayam | G6: =VLOOKUP(C6,Data!$B$2:$G$176,6,FALSE) -> 9961671818 | H6: ILP 2 Commerce | J6: =K6+M6*$L$1-U6 -> 25000 | K6: 20000 | L6: 30000 | M6: =L6/6 -> 5000 | U6: =SUM(N6+P6+Q6+R6+S6+T6) -> 0
A7: =ROW()-3 -> 4 | B7: 4 | C7: HAFIZ MUHAMMED | D7: =VLOOKUP(C7,Data!$B$2:$G$176,3,FALSE) -> ABDUL HAKEEM | E7: =VLOOKUP(C7,Data!$B$2:$G$176,4,FALSE) -> Madathil (H) kanjirappally , Kanjirappally , 9037026538 , | F7: =VLOOKUP(C7,Data!$B$2:$G$176,5,FALSE) -> Kottayam | G7: =VLOOKUP(C7,Data!$B$2:$G$176,6,FALSE) -> 0 | H7: ILP 2 Commerce | J7: =K7+M7*$L$1-U7 -> 10000 | K7: 5000 | L7: 30000 | M7: =L7/6 -> 5000 | U7: =SUM(N7+P7+Q7+R7+S7+T7) -> 0
A8: =ROW()-3 -> 5 | B8: 5 | C8: HASSAN NASRULLA OTTAKATHU | D8: =VLOOKUP(C8,Data!$B$2:$G$176,3,FALSE) -> ABDUL HAKKIM OK | E8: =VLOOKUP(C8,Data!$B$2:$G$176,4,FALSE) -> Urngattiri, Malappuram | F8: =VLOOKUP(C8,Data!$B$2:$G$176,5,FALSE) -> Malappuram | G8: =VLOOKUP(C8,Data!$B$2:$G$176,6,FALSE) -> 9495720921. 8921100921 | H8: ILP 2 Commerce | J8: =K8+M8*$L$1-U8 -> 10000 | K8: 5000 | L8: 30000 | M8: =L8/6 -> 5000 | U8: =SUM(N8+P8+Q8+R8+S8+T8) -> 0
A9: =ROW()-3 -> 6 | B9: 6 | C9: MISHAB IBNU ABDUL LATHEEF | D9: =VLOOKUP(C9,Data!$B$2:$G$176,3,FALSE) -> ABDULLATHEEF PK | E9: =VLOOKUP(C9,Data!$B$2:$G$176,4,FALSE) -> Pokkakkilath (h) kadappuram, chavakkad, Thrissur , Kadappuram | F9: =VLOOKUP(C9,Data!$B$2:$G$176,5,FALSE) -> Thrissur | G9: =VLOOKUP(C9,Data!$B$2:$G$176,6,FALSE) -> 9947258656 | H9: ILP 2 Commerce | J9: =K9+M9*$L$1-U9 -> 5000 | K9: 0 | L9: 30000 | M9: =L9/6 -> 5000 | U9: =SUM(N9+P9+Q9+R9+S9+T9) -> 0
A10: =ROW()-3 -> 7 | B10: 7 | C10: MISHAL JANIB CH | D10: =VLOOKUP(C10,Data!$B$2:$G$176,3,FALSE) -> ASHRAF CH | E10: =VLOOKUP(C10,Data!$B$2:$G$176,4,FALSE) -> Thirurkad PO, Perinthalmanna, , | F10: =VLOOKUP(C10,Data!$B$2:$G$176,5,FALSE) -> Malappuram | G10: =VLOOKUP(C10,Data!$B$2:$G$176,6,FALSE) -> 9846302863 | H10: ILP 2 Commerce | J10: =K10+M10*$L$1-U10 -> 25000 | K10: 20000 | L10: 30000 | M10: =L10/6 -> 5000 | U10: =SUM(N10+P10+Q10+R10+S10+T10) -> 0
A11: =ROW()-3 -> 8 | B11: 8 | C11: MUHAMMAD RAIHAN C | D11: =VLOOKUP(C11,Data!$B$2:$G$176,3,FALSE) -> KASIM.KP | E11: =VLOOKUP(C11,Data!$B$2:$G$176,4,FALSE) -> Rafeena’s Kannavam (po) 670650, Chittariparamba, , | F11: =VLOOKUP(C11,Data!$B$2:$G$176,5,FALSE) -> Kannur | G11: =VLOOKUP(C11,Data!$B$2:$G$176,6,FALSE) -> 9605304984 | H11: ILP 2 Commerce | J11: =K11+M11*$L$1-U11 -> 45000 | K11: 40000 | L11: 30000 | M11: =L11/6 -> 5000 | U11: =SUM(N11+P11+Q11+R11+S11+T11) -> 0
A12: =ROW()-3 -> 9 | B12: 9 | C12: MUHAMMAD SALAHUDHEEN | D12: =VLOOKUP(C12,Data!$B$2:$G$176,3,FALSE) -> ABDULRAHMAN PM | E12: =VLOOKUP(C12,Data!$B$2:$G$176,4,FALSE) -> Vazhakkulam | F12: =VLOOKUP(C12,Data!$B$2:$G$176,5,FALSE) -> Ernakulam | G12: =VLOOKUP(C12,Data!$B$2:$G$176,6,FALSE) -> 9745567659 | H12: ILP 2 Commerce | J12: =K12+M12*$L$1-U12 -> 35000 | K12: 30000 | L12: 30000 | M12: =L12/6 -> 5000 | U12: =SUM(N12+P12+Q12+R12+S12+T12) -> 0
A13: =ROW()-3 -> 10 | B13: 10 | C13: MUHAMMED BILAL CT | D13: =VLOOKUP(C13,Data!$B$2:$G$176,3,FALSE) -> ABDUL JALEEL CHEERAN THODIKA | E13: =VLOOKUP(C13,Data!$B$2:$G$176,4,FALSE) -> Kozhakkodan chalil, Poovathikkal po, Malappuram dt , Kerala st. 673639 | F13: =VLOOKUP(C13,Data!$B$2:$G$176,5,FALSE) -> Malappuram | G13: =VLOOKUP(C13,Data!$B$2:$G$176,6,FALSE) -> 9562487231 8139817331 | H13: ILP 2 Commerce | J13: =K13+M13*$L$1-U13 -> 15000 | K13: 10000 | L13: 30000 | M13: =L13/6 -> 5000 | U13: =SUM(N13+P13+Q13+R13+S13+T13) -> 0
A14: =ROW()-3 -> 11 | B14: 11 | C14: MUHAMMED FARIS M | D14: =VLOOKUP(C14,Data!$B$2:$G$176,3,FALSE) -> MIRSHAD. A | E14: =VLOOKUP(C14,Data!$B$2:$G$176,4,FALSE) -> Thadatharikathu vilayil Veedu melekuttimoodu vellumannadi p.o venjarmoodu , Vamanapuram, , | F14: =VLOOKUP(C14,Data!$B$2:$G$176,5,FALSE) -> Thiruvanathapuram | G14: =VLOOKUP(C14,Data!$B$2:$G$176,6,FALSE) -> 8129655801 | H14: ILP 2 Commerce | J14: =K14+M14*$L$1-U14 -> 45000 | K14: 40000 | L14: 30000 | M14: =L14/6 -> 5000 | U14: =SUM(N14+P14+Q14+R14+S14+T14) -> 0
A15: =ROW()-3 -> 12 | B15: 12 | C15: MUHAMMED HANAN AK | D15: =VLOOKUP(C15,Data!$B$2:$G$176,3,FALSE) -> ASHRAF AK | E15: =VLOOKUP(C15,Data!$B$2:$G$176,4,FALSE) -> lakandi house kattayad po vellamunda Wayanad 670731, Mananthavady, , | F15: =VLOOKUP(C15,Data!$B$2:$G$176,5,FALSE) -> Wayanad | G15: =VLOOKUP(C15,Data!$B$2:$G$176,6,FALSE) -> 9188500411 | H15: ILP 2 Commerce | J15: =K15+M15*$L$1-U15 -> 15000 | K15: 10000 | L15: 30000 | M15: =L15/6 -> 5000 | U15: =SUM(N15+P15+Q15+R15+S15+T15) -> 0
... A25: =ROW()-3 -> 22 | B25: 22 | C25: SAFWAN | D25: =VLOOKUP(C25,Data!$B$2:$G$176,3,FALSE) -> NAZIR P | E25: =VLOOKUP(C25,Data!$B$2:$G$176,4,FALSE) -> ASYAS, NEAR MGGA COLLEGE, CHALAKKARA , MAHE | F25: =VLOOKUP(C25,Data!$B$2:$G$176,5,FALSE) -> Mahe | G25: =VLOOKUP(C25,Data!$B$2:$G$176,6,FALSE) -> 7012742084. 8015384390 | H25: ILP 2 Commerce | J25: =K25+M25*$L$1-U25 -> 15000 | K25: 10000 | L25: 30000 | M25: =L25/6 -> 5000 | U25: =SUM(N25+P25+Q25+R25+S25+T25) -> 0
A26: =ROW()-3 -> 23 | C26: AHMED SANHEER MTP | D26: =VLOOKUP(C26,Data!$B$2:$G$176,3,FALSE) -> 0 | E26: =VLOOKUP(C26,Data!$B$2:$G$176,4,FALSE) | F26: =VLOOKUP(C26,Data!$B$2:$G$176,5,FALSE) -> 0 | G26: =VLOOKUP(C26,Data!$B$2:$G$176,6,FALSE) | H26: ILP 2 Humanities | J26: =K26+M26*$L$1-U26 -> 10000 | K26: 5000 | L26: 30000 | M26: =L26/6 -> 5000 | U26: =SUM(N26+P26+Q26+R26+S26+T26) -> 0
A27: =ROW()-3 -> 24 | C27: ANZAM MIRZAD | D27: =VLOOKUP(C27,Data!$B$2:$G$176,3,FALSE) -> SAIFUDHEEN TA | E27: =VLOOKUP(C27,Data!$B$2:$G$176,4,FALSE) -> Thathampara (h)nadackal p. o erattupetta, Erattupetta, , | F27: =VLOOKUP(C27,Data!$B$2:$G$176,5,FALSE) -> Kottayam | G27: =VLOOKUP(C27,Data!$B$2:$G$176,6,FALSE) -> 8281750889 | H27: ILP 2 Humanities | J27: =K27+M27*$L$1-U27 -> 10000 | K27: 5000 | L27: 30000 | M27: =L27/6 -> 5000 | U27: =SUM(N27+P27+Q27+R27+S27+T27) -> 0
A28: =ROW()-3 -> 25 | C28: ASHHAD M | D28: =VLOOKUP(C28,Data!$B$2:$G$176,3,FALSE) -> ABDUL GAFOOR.M | E28: =VLOOKUP(C28,Data!$B$2:$G$176,4,FALSE) -> Melethil house, Pulluvanpadi, Kalady post , KALADI panchayath | F28: =VLOOKUP(C28,Data!$B$2:$G$176,5,FALSE) -> Malappuram | G28: =VLOOKUP(C28,Data!$B$2:$G$176,6,FALSE) -> 0 | H28: ILP 2 Humanities | J28: =K28+M28*$L$1-U28 -> 10000 | K28: 5000 | L28: 30000 | M28: =L28/6 -> 5000 | U28: =SUM(N28+P28+Q28+R28+S28+T28) -> 0
A29: =ROW()-3 -> 26 | C29: HASSAN S | D29: =VLOOKUP(C29,Data!$B$2:$G$176,3,FALSE) -> HASEENA SHIHAB | E29: =VLOOKUP(C29,Data!$B$2:$G$176,4,FALSE) -> Kochukoikkal, Thaliradi, kaduvinal PO , Vallikunnam | F29: =VLOOKUP(C29,Data!$B$2:$G$176,5,FALSE) -> Alappuzha | G29: =VLOOKUP(C29,Data!$B$2:$G$176,6,FALSE) -> 963384242 | H29: ILP 2 Humanities | J29: =K29+M29*$L$1-U29 -> 7500 | K29: 2500 | L29: 30000 | M29: =L29/6 -> 5000 | U29: =SUM(N29+P29+Q29+R29+S29+T29) -> 0
A30: =ROW()-3 -> 27 | C30: MUHAMMAD FAROOK S | D30: =VLOOKUP(C30,Data!$B$2:$G$176,3,FALSE) -> SUBER KUNJU | E30: =VLOOKUP(C30,Data!$B$2:$G$176,4,FALSE) -> Kanjiravila kizhakkathil, chola puthenchantha PO, 691583 ,KOLLAM | F30: =VLOOKUP(C30,Data!$B$2:$G$176,5,FALSE) -> Kollam | G30: =VLOOKUP(C30,Data!$B$2:$G$176,6,FALSE) -> 7994146350 | H30: ILP 2 Humanities | J30: =K30+M30*$L$1-U30 -> 65000 | K30: 60000 | L30: 30000 | M30: =L30/6 -> 5000 | U30: =SUM(N30+P30+Q30+R30+S30+T30) -> 0
A31: =ROW()-3 -> 28 | C31: MUHAMMAD JUBAIR PA | D31: =VLOOKUP(C31,Data!$B$2:$G$176,3,FALSE) -> ABDUL KABEER P.Y | E31: =VLOOKUP(C31,Data!$B$2:$G$176,4,FALSE) -> PALLATH (H) PATHIYASSERY, PO. PATHAZHAKKADU, KODUGALLOOR ,THRISSUR | F31: =VLOOKUP(C31,Data!$B$2:$G$176,5,FALSE) -> THRISSUR | G31: =VLOOKUP(C31,Data!$B$2:$G$176,6,FALSE) -> 0 | H31: ILP 2 Humanities | J31: =K31+M31*$L$1-U31 -> 20000 | K31: 15000 | L31: 30000 | M31: =L31/6 -> 5000 | U31: =SUM(N31+P31+Q31+R31+S31+T31) -> 0
A32: =ROW()-3 -> 29 | C32: MUHAMMED ASIF M | D32: =VLOOKUP(C32,Data!$B$2:$G$176,3,FALSE) -> MOHAMMED IQBAL SM | E32: =VLOOKUP(C32,Data!$B$2:$G$176,4,FALSE) -> ATHANIKKAL, PERITHALMANNA , , | F32: =VLOOKUP(C32,Data!$B$2:$G$176,5,FALSE) -> MALAPURAM | G32: =VLOOKUP(C32,Data!$B$2:$G$176,6,FALSE) -> 9745903145 | H32: ILP 2 Humanities | J32: =K32+M32*$L$1-U32 -> 10000 | K32: 5000 | L32: 30000 | M32: =L32/6 -> 5000 | U32: =SUM(N32+P32+Q32+R32+S32+T32) -> 0
A33: =ROW()-3 -> 30 | C33: MUHAMMED BILAL | D33: =VLOOKUP(C33,Data!$B$2:$G$176,3,FALSE) -> അബുൽ ബഷീർ MT | E33: =VLOOKUP(C33,Data!$B$2:$G$176,4,FALSE) -> Naduvannur Moolad | F33: =VLOOKUP(C33,Data!$B$2:$G$176,5,FALSE) -> Kozhikkode | G33: =VLOOKUP(C33,Data!$B$2:$G$176,6,FALSE) -> 9946501154 8943671154 | H33: ILP 2 Humanities | J33: =K33+M33*$L$1-U33 -> 10000 | K33: 5000 | L33: 30000 | M33: =L33/6 -> 5000 | U33: =SUM(N33+P33+Q33+R33+S33+T33) -> 0
A34: =ROW()-3 -> 31 | C34: MUHAMMED JASIL K | D34: =VLOOKUP(C34,Data!$B$2:$G$176,3,FALSE) -> RAISHAL BABU K | E34: =VLOOKUP(C34,Data!$B$2:$G$176,4,FALSE) -> Karuvalli (H) Kadungapuram (Po) Angadippuram (via) Malappuram (Dt) Pin: 679321, Mankada, , | F34: =VLOOKUP(C34,Data!$B$2:$G$176,5,FALSE) -> Malappuram | G34: =VLOOKUP(C34,Data!$B$2:$G$176,6,FALSE) -> 9946459008 | H34: ILP 2 Humanities | J34: =K34+M34*$L$1-U34 -> 30000 | K34: 25000 | L34: 30000 | M34: =L34/6 -> 5000 | U34: =SUM(N34+P34+Q34+R34+S34+T34) -> 0
A35: =ROW()-3 -> 32 | C35: MUHAMMED MUKHTHAR CT | D35: =VLOOKUP(C35,Data!$B$2:$G$176,3,FALSE) -> MUJEEB RAHMAN CT | E35: =VLOOKUP(C35,Data!$B$2:$G$176,4,FALSE) -> CHETTIYAMTHODI HOUSE, PARAMBOOR, PATTIKKAD PO. 679325 ,MALAPPURAM. | F35: =VLOOKUP(C35,Data!$B$2:$G$176,5,FALSE) -> MALAPPURAM. | G35: =VLOOKUP(C35,Data!$B$2:$G$176,6,FALSE) -> 9633812737 | H35: ILP 2 Humanities | J35: =K35+M35*$L$1-U35 -> 10000 | K35: 5000 | L35: 30000 | M35: =L35/6 -> 5000 | U35: =SUM(N35+P35+Q35+R35+S35+T35) -> 0
A36: =ROW()-3 -> 33 | C36: MUHAMMED NAZAL | D36: =VLOOKUP(C36,Data!$B$2:$G$176,3,FALSE) -> NAVAF AP | E36: =VLOOKUP(C36,Data!$B$2:$G$176,4,FALSE) -> Arukulampurath house . payyoli angadi post 673523 pin, Thurayur, 7902415813 8089815813 , | F36: =VLOOKUP(C36,Data!$B$2:$G$176,5,FALSE) -> Kozhikode | G36: =VLOOKUP(C36,Data!$B$2:$G$176,6,FALSE) -> 8089815813 | H36: ILP 2 Humanities | J36: =K36+M36*$L$1-U36 -> 20000 | K36: 15000 | L36: 30000 | M36: =L36/6 -> 5000 | U36: =SUM(N36+P36+Q36+R36+S36+T36) -> 0
A37: =ROW()-3 -> 34 | C37: MUHAMMED RAKEEB | D37: =VLOOKUP(C37,Data!$B$2:$G$176,3,FALSE) -> RAJEENA. L(MOTHER ) | E37: =VLOOKUP(C37,Data!$B$2:$G$176,4,FALSE) -> Darul salam. Kalluvarambu. Poovathoor. P O. Nedumangad. 695561, Muncipqlity. Nedumangad , 8921974141/9207464684 , | F37: =VLOOKUP(C37,Data!$B$2:$G$176,5,FALSE) -> Trivandrum | G37: =VLOOKUP(C37,Data!$B$2:$G$176,6,FALSE) -> 9207464684 | H37: ILP 2 Humanities | J37: =K37+M37*$L$1-U37 -> 10000 | K37: 5000 | L37: 30000 | M37: =L37/6 -> 5000 | U37: =SUM(N37+P37+Q37+R37+S37+T37) -> 0
... A94: =ROW()-3 -> 91 | C94: MUHAMMED SHINAS K | D94: =VLOOKUP(C94,Data!$B$2:$G$176,3,FALSE) -> SHARAFUDHEEN K | E94: =VLOOKUP(C94,Data!$B$2:$G$176,4,FALSE) -> Anju Kunnu Wayanad8086063002 | F94: =VLOOKUP(C94,Data!$B$2:$G$176,5,FALSE) -> Wayanad | G94: =VLOOKUP(C94,Data!$B$2:$G$176,6,FALSE) -> 8086063002 | H94: ILP 4 soc | J94: =K94+M94*$L$1-U94 -> 25000 | K94: 20000 | L94: 30000 | M94: =L94/6 -> 5000 | U94: =SUM(N94+P94+Q94+R94+S94+T94) -> 0
C95: MUHAMMED SINAN VK | D95: =VLOOKUP(C95,Data!$B$2:$G$176,3,FALSE) -> ABOOBAKER | E95: =VLOOKUP(C95,Data!$B$2:$G$176,4,FALSE) -> Shukhapuram Malappuram9645268067 | F95: =VLOOKUP(C95,Data!$B$2:$G$176,5,FALSE) -> Malappuram | G95: =VLOOKUP(C95,Data!$B$2:$G$176,6,FALSE) -> 9645268067 | H95: ILP 4 bca | J95: =K95+M95*$L$1-U95 -> 15000 | K95: 10000 | L95: 30000 | M95: =L95/6 -> 5000 | U95: =SUM(N95+P95+Q95+R95+S95+T95) -> 0
A96: =ROW()-3 -> 93 | C96: NABEEL N | D96: =VLOOKUP(C96,Data!$B$2:$G$176,3,FALSE) -> ABDUL GAFOOR N | E96: =VLOOKUP(C96,Data!$B$2:$G$176,4,FALSE) -> Malappuram 6933160027 | F96: =VLOOKUP(C96,Data!$B$2:$G$176,5,FALSE) -> Malappuram | G96: =VLOOKUP(C96,Data!$B$2:$G$176,6,FALSE) -> 6933160027 | H96: ILP 4 bca | J96: =K96+M96*$L$1-U96 -> 5000 | K96: 0 | L96: 30000 | M96: =L96/6 -> 5000 | U96: =SUM(N96+P96+Q96+R96+S96+T96) -> 0
A97: =ROW()-3 -> 94 | C97: RAZI HANAN CK | D97: =VLOOKUP(C97,Data!$B$2:$G$176,3,FALSE) -> LATHEEF | E97: =VLOOKUP(C97,Data!$B$2:$G$176,4,FALSE) -> Kannur 8921111512 | F97: =VLOOKUP(C97,Data!$B$2:$G$176,5,FALSE) -> Kannur | G97: =VLOOKUP(C97,Data!$B$2:$G$176,6,FALSE) -> 8921111512 | H97: ILP 4 soc | J97: =K97+M97*$L$1-U97 -> 106000 | K97: 101000 | L97: 30000 | M97: =L97/6 -> 5000 | U97: =SUM(N97+P97+Q97+R97+S97+T97) -> 0
A98: =ROW()-3 -> 95 | C98: SABEER AHAMMED | D98: =VLOOKUP(C98,Data!$B$2:$G$176,3,FALSE) -> SIKANDER | E98: =VLOOKUP(C98,Data!$B$2:$G$176,4,FALSE) -> 0 | F98: =VLOOKUP(C98,Data!$B$2:$G$176,5,FALSE) -> Coimbathur | G98: =VLOOKUP(C98,Data!$B$2:$G$176,6,FALSE) -> 6382623643 | H98: ILP 4 bca | J98: =K98+M98*$L$1-U98 -> 55000 | K98: 50000 | L98: 30000 | M98: =L98/6 -> 5000 | U98: =SUM(N98+P98+Q98+R98+S98+T98) -> 0
A99: =ROW()-3 -> 96 | C99: SALMAN FARIS M | D99: =VLOOKUP(C99,Data!$B$2:$G$176,3,FALSE) -> HANEEFA M | E99: =VLOOKUP(C99,Data!$B$2:$G$176,4,FALSE) -> Mattanur Kannur | F99: =VLOOKUP(C99,Data!$B$2:$G$176,5,FALSE) -> Kannur | G99: =VLOOKUP(C99,Data!$B$2:$G$176,6,FALSE) -> 0 | H99: ILP 4 bca | J99: =K99+M99*$L$1-U99 -> 95000 | K99: 90000 | L99: 30000 | M99: =L99/6 -> 5000 | U99: =SUM(N99+P99+Q99+R99+S99+T99) -> 0
A100: =ROW()-3 -> 97 | C100: ADHIL AHAMMED | D100: =VLOOKUP(C100,Data!$B$2:$G$176,3,FALSE) -> NIZZAR PH | E100: =VLOOKUP(C100,Data!$B$2:$G$176,4,FALSE) -> Erumely 8078866268 | F100: =VLOOKUP(C100,Data!$B$2:$G$176,5,FALSE) -> Kottayam | G100: =VLOOKUP(C100,Data!$B$2:$G$176,6,FALSE) -> 8078866268 | H100: ILP 5 B.Com | J100: =K100+M100*$L$1-U100 -> 1500 | K100: 0 | L100: 9000 | M100: =L100/6 -> 1500 | U100: =SUM(N100+P100+Q100+R100+S100+T100) -> 0
A101: =ROW()-3 -> 98 | C101: AMAL THAHSEEN | D101: =VLOOKUP(C101,Data!$B$2:$G$176,3,FALSE) -> RAHEEM MP | E101: =VLOOKUP(C101,Data!$B$2:$G$176,4,FALSE) -> Panamaram8281276160 | F101: =VLOOKUP(C101,Data!$B$2:$G$176,5,FALSE) -> Wayanad | G101: =VLOOKUP(C101,Data!$B$2:$G$176,6,FALSE) -> 8281276160 | H101: ILP 5 B.Com | J101: =K101+M101*$L$1-U101 -> 10500 | K101: 9000 | L101: 9000 | M101: =L101/6 -> 1500 | U101: =SUM(N101+P101+Q101+R101+S101+T101) -> 0
A102: =ROW()-3 -> 99 | C102: AMALTHAHASIN CH | D102: =VLOOKUP(C102,Data!$B$2:$G$176,3,FALSE) -> 0 | E102: =VLOOKUP(C102,Data!$B$2:$G$176,4,FALSE) | F102: =VLOOKUP(C102,Data!$B$2:$G$176,5,FALSE) -> Wayanad | G102: =VLOOKUP(C102,Data!$B$2:$G$176,6,FALSE) | H102: ILP 5 B.Com | J102: =K102+M102*$L$1-U102 -> 12000 | K102: 8000 | L102: 24000 | M102: =L102/6 -> 4000 | U102: =SUM(N102+P102+Q102+R102+S102+T102) -> 0
A103: =ROW()-3 -> 100 | C103: HADIF V | D103: =VLOOKUP(C103,Data!$B$2:$G$176,3,FALSE) -> JAIFER | E103: =VLOOKUP(C103,Data!$B$2:$G$176,4,FALSE) -> Rippon7558861406 | F103: =VLOOKUP(C103,Data!$B$2:$G$176,5,FALSE) -> Wayanad | G103: =VLOOKUP(C103,Data!$B$2:$G$176,6,FALSE) -> 7558861406 | H103: ILP 5 B.Com | J103: =K103+M103*$L$1-U103 -> 8000 | K103: 4000 | L103: 24000 | M103: =L103/6 -> 4000 | U103: =SUM(N103+P103+Q103+R103+S103+T103) -> 0
A104: =ROW()-3 -> 101 | C104: MISBAHUL HAQUE | D104: =VLOOKUP(C104,Data!$B$2:$G$176,3,FALSE) -> ISMAIL | E104: =VLOOKUP(C104,Data!$B$2:$G$176,4,FALSE) -> Kodiyra8943898320 | F104: =VLOOKUP(C104,Data!$B$2:$G$176,5,FALSE) -> Kozhikode | G104: =VLOOKUP(C104,Data!$B$2:$G$176,6,FALSE) -> 8943898320 | H104: ILP 5 B.Com | J104: =K104+M104*$L$1-U104 -> 12000 | K104: 8000 | L104: 24000 | M104: =L104/6 -> 4000 | U104: =SUM(N104+P104+Q104+R104+S104+T104) -> 0
A105: =ROW()-3 -> 102 | C105: MUHAMMED ALTHAF KODANJERY | D105: =VLOOKUP(C105,Data!$B$2:$G$176,3,FALSE) -> ADBUL HAKKEM | E105: =VLOOKUP(C105,Data!$B$2:$G$176,4,FALSE) -> Nudumangad Thiruvanathapuram9400767278 | F105: =VLOOKUP(C105,Data!$B$2:$G$176,5,FALSE) -> Thiruvanathapuram | G105: =VLOOKUP(C105,Data!$B$2:$G$176,6,FALSE) -> 9400767278 | H105: ILP 5 B.Com | J105: =K105+M105*$L$1-U105 -> 8000 | K105: 4000 | L105: 24000 | M105: =L105/6 -> 4000 | U105: =SUM(N105+P105+Q105+R105+S105+T105) -> 0
A106: =ROW()-3 -> 103 | C106: MUHAMMED FAHAD NN | D106: =VLOOKUP(C106,Data!$B$2:$G$176,3,FALSE) -> NISSAR AHMMED | E106: =VLOOKUP(C106,Data!$B$2:$G$176,4,FALSE) -> Mannam9961132274 | F106: =VLOOKUP(C106,Data!$B$2:$G$176,5,FALSE) -> Ernakulam | G106: =VLOOKUP(C106,Data!$B$2:$G$176,6,FALSE) -> 9961132274 | H106: ILP 5 B.Com | J106: =K106+M106*$L$1-U106 -> 8000 | K106: 4000 | L106: 24000 | M106: =L106/6 -> 4000 | U106: =SUM(N106+P106+Q106+R106+S106+T106) -> 0
...

Sheet Individual
A1: Greenvalley Academy
A3: Semester Fee Remittance Details 2026-27
A4: Name of the Student | B4: NIHAD KP | D4: Admission No
A5: Class | B5: {=_xludf.xlookup(B4,Table1[Name],Table1[Class])} -> #NAME? | D5: Phone No | E5: {=_xludf.xlookup(B4,Table1[Name],Table1[PHONE])} -> #NAME?
A6: Name of Parent | B6: {=_xludf.xlookup(B4,Table1[Name],Table1[Name of Father])} -> #NAME? | D6: District | E6: {=_xludf.xlookup(B4,Table1[Name],Table1[DISTRICT])} -> #NAME?
A7: Address | B7: {=_xludf.xlookup(B4,Table1[Name],Table1[ADDRESS])} -> #NAME?
A8: Month | B8: Amount Recieved | C8: Reciept No | D8: Month | E8: Amount Recieved | F8: Reciept No
A9: 46174 | B9: {=_xludf.xlookup(B4,Table1[Name],Table1[JUNE])} -> #NAME? | C9: {=_xludf.xlookup(B4,Table1[Name],Table1[JuneReciept])} -> #NAME? | D9: 46357 | E9: {=_xludf.xlookup(B4,Table1[Name],Table1[DEC])} -> #NAME?
A10: 46204 | B10: {=_xludf.xlookup(B4,Table1[Name],Table1[JULY])} -> #NAME? | D10: 46388 | E10: {=_xludf.xlookup(B4,Table1[Name],Table1[Jan])} -> #NAME?
A11: 46235 | B11: {=_xludf.xlookup(B4,Table1[Name],Table1[AUG])} -> #NAME? | D11: 46419 | E11: {=_xludf.xlookup(B4,Table1[Name],Table1[FEB])} -> #NAME?
A12: 46266 | B12: {=_xludf.xlookup(B4,Table1[Name],Table1[SEP])} -> #NAME? | D12: 46447 | E12: {=_xludf.xlookup(B4,Table1[Name],Table1[MAR])} -> #NAME?
A13: 46296 | B13: {=_xludf.xlookup(B4,Table1[Name],Table1[OCT])} -> #NAME? | D13: 46478 | E13: {=_xludf.xlookup(B4,Table1[Name],Table1[APR])} -> #NAME?
A14: 46327 | B14: {=_xludf.xlookup(B4,Table1[Name],Table1[NOV])} -> #NAME? | D14: 46508 | E14: {=_xludf.xlookup(B4,Table1[Name],Table1[May])} -> #NAME?
A15: Outstanding Amount Due on : | D15: =TODAY() -> 46181 | E15: {=_xludf.xlookup(B4,Sheet1!C4:C184,Sheet1!J4:J184)} -> #NAME?

Sheet Data
A1: sl no | B1: name of student | D1: Name of Guardian | E1: Address | F1: district | G1: Phone No
A2: 1 | B2: AALIYA PJ
A3: 2 | B3: AAYISHA SHAHUL | C3: ILS 2 | D3: BIJU S P | E3: Gandhinagar junction chullimanoor PO7736292196 | F3: Thiruvanadapuram | G3: 7736292196
A4: 3 | B4: ABDUL SATHAR | C4: ILP 5 | E4: Elippakulam 9995512047 | F4: Alappuzha | G4: 9995512047
A5: 4 | B5: ABID ISMAIL | C5: C1 | D5: V.U ISMAYEL | E5: Darul Aman (H), Vanchimala PO, Vanchimala (686508) , Elikkulam Panchayath | F5: Kottayam | G5: 9496432300
A6: 5 | B6: ADHIL AHAMMED | C6: ILP 4 | D6: NIZZAR PH | E6: Erumely 8078866268 | F6: Kottayam | G6: 8078866268
A7: 6 | B7: ADHIL RAHMAN MK | C7: H2 | D7: ABDUL RAZAK MK | E7: MANGALOTTKUNNUMMAL ELETTIL ELETTIL PO | F7: Kozhikkode | G7: 9745387167
A8: 7 | B8: AFSAL AMEEN PV | C8: C1 | D8: ALI AKBAR P.V | E8: Pallikaravalappil, Wandoor, 8547225367 , | F8: Malappuram
A9: 8 | B9: AHAMMAD YASEEN N | C9: ILP 4 | D9: NASIR KHALID | E9: Mannoorkoonam 9567277882 | F9: Thiruvanathapuram | G9: 9567277882
A10: 9 | B10: AHAMMAD YASEEN S | C10: ILP 4 | D10: SAJEEV B | E10: Vakkam 9567572262 | F10: Thiruvanathapuram | G10: 9567572262
A11: 10 | B11: AHAMMED YASEEN | C11: C2 | D11: ABDUL NAUSHAD T A | E11: Thundiyil Murickassery Murickassery PO | F11: Idukki | G11: 9744376726
A12: 11 | B12: AHMED SANHEER MTP | C12: H1
A13: 12 | B13: AHSAS CP | C13: ILP 3 | D13: ASHRAF CP | E13: Malappuram, 9995505516 | F13: Malappuram | G13: 9995505516
A14: 13 | B14: AJUMAL VY | C14: H2 | D14: YOONUZ VA | E14: Padinjare vathuthara niranam north po thiruvalla9656401054 | F14: Pathanamthitta | G14: 9656401054
A15: 14 | B15: ALI SYED BS | C15: H2 | D15: BIJU S | E15: Kizakkumkara Veedu Neetani Poonkavanam Cullimanoor P O Anad PO 7902864924 | F15: Thiruvanathapuram | G15: 7902864924
A16: 15 | B16: ALTHAF VAHAB VA (SOC) | C16: ILP 4 | D16: VAHAB A | E16: Aluva9544352760 | F16: Ernakulam | G16: 9544352760
A17: 16 | B17: AMAL THAHSEEN | C17: ILP 4 | D17: RAHEEM MP | E17: Panamaram8281276160 | F17: Wayanad | G17: 8281276160
A18: 17 | B18: AMALTHAHASIN CH | C18: ILP 4 | F18: Wayanad
A19: 18 | B19: AMEEN KT | C19: C2 | D19: MUHAMMED SHAFEEQUE | E19: Koyathodukayil housekodakkad Po676319 | F19: Malappuram | G19: 9544693218
A20: 19 | B20: AMEEN MUHAMMED VN | C20: H2 | D20: NISSAMUDEEN V.I | E20: Varikkatu(H) chennappady (po) kottayam9605438110 | F20: Kottayam | G20: 9605438110
A21: 20 | B21: AMEENA FATHIMA | C21: ILS 2 | D21: MUEENUDDEEN | E21: Cheriya Parambath Muthuvadathoor PO Kozhikode | F21: Kozhikkode | G21: 9072300000
A22: 21 | B22: ANAS S | C22: ILP 3
A23: 22 | B23: ANSHAD N | C23: C2 | D23: HAFSATH.K | E23: Nelliyali(h) chamravettom chamravettom p.o tirurmalappuram | F23: Malappuram | G23: 7034768747
A24: 23 | B24: ANZAM MIRZAD | C24: H1 | D24: SAIFUDHEEN TA | E24: Thathampara (h)nadackal p. o erattupetta, Erattupetta, , | F24: Kottayam | G24: 8281750889
A25: 24 | B25: ASHHAD M | C25: H1 | D25: ABDUL GAFOOR.M | E25: Melethil house, Pulluvanpadi, Kalady post , KALADI panchayath | F25: Malappuram
A26: 25 | B26: ASHIK MUHAMMED N | C26: ILP 3 | D26: NOUSHAD S | E26: Njarayilkonam Thiruvanathapuram9656185571 | F26: Thiruvanathapuram | G26: 9656185571
A27: 26 | B27: AYISHA SULTHANA VM | C27: ILS 2 | D27: MUHAMMED ASHARAF V K | E27: Vadavanakudy House Ponjassery PO Hidayath Nagar Perumbavoor Eranakulam68354795394855378943800000 | F27: Eranamkulam | G27: 8943800000
A28: 27 | B28: FARHANA FATHIMA M | C28: ILS 2 | D28: MUNIR.M | E28: Kottakkara Vadakkadil ManappallyPO Karunagappallykollam8714910688 | F28: Kollam | G28: 8714910688
A29: 28 | B29: FARSEEN AHAMMED EP | C29: ILP 4 | D29: KUNHIKOYA | E29: Tanur7356416112 | F29: Malappuram | G29: 7356416112
A30: 29 | B30: FATHAHUDEEN S | C30: C2 | D30: SHAJEER KHAN | E30: Fathima Manzil Chembran Kadu Koduvazhannoor PO | F30: Thiruvanathapuram | G30: 9645257053
A31: 30 | B31: FATHIMA CA | C31: ILS 2 | D31: MUHAMMED ANVAR | G31: 8593847672
A32: 31 | B32: FATHIMA JAHAN | C32: ILS 2 | D32: ABDUL MAJEED K K | E32: Vattapparakkal (H) karuvanpoyil (p.o) koduvally 9539350360 | F32: Kozhikkode | G32: 9539350360
A33: 32 | B33: FATHIMA JASNA | C33: ILS 1 | D33: MOHAMMED ASHRAF | E33: Kozhikkodan Edarikkode Malappuram | F33: Malappuram | G33: 9400404055
A34: 33 | B34: FATHIMA SAHARA | C34: ILS 2 | D34: ABDUL BASHEER M T | E34: ThirumangalamKunnaramvelliMoolad P.O Naduvannur via 673614 | F34: Kozhikkode | G34: 9946501154
A35: 34 | B35: FATHIMA SHADIYA M | C35: ILS 1 | D35: MOHAMMED MIDHLAJ | E35: Machingal house Naripparamb (po) kalady | F35: Malappuram | G35: 9037865355
A36: 35 | B36: FATHIMATH HANNA | C36: ILS 2 | D36: MUHAMMED RIYAS | E36: Kizhakkanadan Karinkallathani/perinthalmanna 9510417901 | F36: Malappuram | G36: 9510417901
A37: 36 | B37: FATHIMATH SANAH KT | C37: ILS 2 | D37: YOUSAF | E37: Kondoorkkara Thodi H Karakad Kondoorkkara PO | F37: Palakkad | G37: 9745905408
A38: 37 | B38: FAYAS V | C38: ILP 4 | D38: SHAREEF V | E38: Ponmala9034146268 | F38: Malappuram | G38: 9034146268
A39: 38 | B39: FIDA NK | C39: ILS 2 | D39: ABOOBACKER NK | E39: Naduvath kalathil Kadappuram mottammal kaattilanghadi PO | F39: Malappuram | G39: 8921510371
A40: 39 | B40: FIDA SHERIN KM | C40: ILS 2 | D40: AYOOB K M | E40: kmayoob949@gmail.com9778191206 | G40: 9778191206
...
